Workbook

Sheet Read Me
A1: Workday Worker Fields Handbook
A2: Built from Worker_PBO.xlsx (primary business object fields) and Worker_RBO.xlsx (related business objects).
A4: At a glance
A5: Total Worker fields (PBO) | B5: =COUNTA('All Worker Fields'!A:A)-1 -> 3254
A6: Workday Delivered fields | B6: =COUNTIF('All Worker Fields'!C:C,"Workday Delivered") -> 2835
A7: Calculated fields | B7: =COUNTIF('All Worker Fields'!C:C,"Calculated") -> 408
A8: Custom fields | B8: =COUNTIF('All Worker Fields'!C:C,"Custom Field") -> 11
A9: Related business objects (RBO) | B9: =COUNTA('Related Objects'!A5:A2000) -> 635
A10: Curated common fields in this handbook | B10: =COUNTA('Common Fields'!C:C)-1 -> 178
A12: Tabs
A13: Common Fields | B13: The handbook: 178 commonly used Worker fields in 11 sections, each with type, related object, description, prompts, usage area and a practical tip. Start here.
A14: Field Types | B14: What each field type means and how to use it in reports and calculated fields, with live counts from the full catalog.
A15: Categories | B15: Every PBO category with its field count, to help you browse the full catalog.
A16: Related Objects | B16: All 635 related business objects from the RBO file, with the number of Worker fields that link to each and example linking fields.
A17: All Worker Fields | B17: The complete PBO catalog (3,254 fields), filterable. Rows marked "Yes" in the Common column are in the handbook.
A19: Column guide
A20: Field Name | B20: Field name exactly as it appears in Workday report writer and calculated fields.
A21: Field Type | B21: Data type returned (see the Field Types tab). Instance types return objects you can drill into.
A22: Related Business Object | B22: The object an instance field returns. Blank for simple types (Text, Date, Numeric, etc.).
A23: Field Source | B23: Workday Delivered, Calculated (tenant calculated field) or Custom Field.
A24: Built-in Prompts | B24: Parameters the field needs (for example As Of, End Date). Fields with prompts behave differently in reports.
A25: Category | B25: Workday field category; useful in the report-writer field picker.
A26: Authorized Usage | B26: Where the field may be used (Default Areas = general reporting; others such as Benefits Eligibility or Security Attribute are restricted contexts).
A27: Handbook Tip | B27: Practical guidance written for this handbook (not from the source files).
A29: Note | B29: Field names, types, descriptions, prompts, categories and usage come from your PBO/RBO exports. Section groupings and tips are editorial guidance; check field behavior in your tenant before using it in production reports. Sensitive fields (personal, demographic, national IDs, compensation) are subject to domain security.

Sheet Common Fields
A1: Commonly Used Worker Fields
A2: Curated from the Worker PBO. Filter by Section or Field Type; the Handbook Tip column is practical guidance.
A4: # | B4: Section | C4: Field Name | D4: Field Type | E4: Related Business Object | F4: Description | G4: Field Source | H4: Built-in Prompts | I4: Category | J4: Authorized Usage | K4: Handbook Tip
A5: 1 | B5: 1. Identity & Name | C5: Worker | D5: Self referencing instance | E5: Worker | F5: Identifies the worker and enables you to view and access related details and actions on the worker. | G5: Workday Delivered | I5: Benefits Eligibility | J5: Security Attribute - System User | K5: The worker instance itself. Use as the first column in most reports; drill into it for any related data.
A6: 2 | B6: 1. Identity & Name | C6: Employee ID | D6: Text | F6: The Employee ID or Contingent Worker ID for the worker. | G6: Workday Delivered | I6: Benefits Eligibility | J6: Benefits Eligibility | K6: Primary key for integrations and matching across systems. Text, so keep leading zeros.
A7: 3 | B7: 1. Identity & Name | C7: Legal Name | D7: Single instance | E7: Global Name Interface | F7: The current legal name of a worker, without an effective date. It displays in the General Name Display Format set in Edit Tenant Setup - System task. Use the Legal Name (Effective Dated) report field if you need the effective date of the ~worker’s~ legal name. | G7: Workday Delivered | I7: Name | J7: Default Areas | K7: Official name, used on payroll, tax and legal documents.
A8: 4 | B8: 1. Identity & Name | C8: Legal Name - First Name | D8: Text | F8: The worker's legal first or given name. | G8: Workday Delivered | I8: Name | J8: Default Areas | K8: Use the split name parts for mail-merge and file layouts.
A9: 5 | B9: 1. Identity & Name | C9: Legal Name - Middle Name | D9: Text | F9: The worker's legal middle name. | G9: Workday Delivered | I9: Name | J9: Default Areas
A10: 6 | B10: 1. Identity & Name | C10: Legal Name - Last Name | D10: Text | F10: The worker's legal family name. | G10: Workday Delivered | I10: Name | J10: Default Areas | K10: Sort or group directories by this field.
A11: 7 | B11: 1. Identity & Name | C11: Full Legal Name | D11: Text | F11: Returns Full Legal Name in Long Name Format. For Malaysia and Singapore returns Full Name (Full Person Name attribute of Global Person Name class) if defined. | G11: Workday Delivered | I11: Name | J11: Default Areas | K11: Single text string of the full legal name; handy for exports.
A12: 8 | B12: 1. Identity & Name | C12: Preferred Name | D12: Single instance | E12: Global Name Interface | F12: Returns the worker's preferred name. | G12: Workday Delivered | I12: Name | J12: Default Areas | K12: Name the worker chooses to be called; use for directories, org charts and emails.
A13: 9 | B13: 1. Identity & Name | C13: Preferred Name - First Name | D13: Text | F13: The worker's preferred first or given name. | G13: Workday Delivered | I13: Name | J13: Default Areas
A14: 10 | B14: 1. Identity & Name | C14: Preferred Name - Last Name | D14: Text | F14: The worker's preferred family name. | G14: Workday Delivered | I14: Name | J14: Default Areas
A15: 11 | B15: 1. Identity & Name | C15: User Name | D15: Text | F15: Contains the User Name associated with the Workday Account | G15: Workday Delivered | I15: Workday Account | J15: Default Areas | K15: Workday account sign-in name; useful for SSO and provisioning checks.
A16: 12 | B16: 1. Identity & Name | C16: Universal Id | D16: Text | F16: Universal Id for the Worker | G16: Workday Delivered | I16: Basic Bio | J16: Default Areas | K16: Cross-system person identifier, when your tenant uses Universal ID.
A17: 13 | B17: 1. Identity & Name | C17: Person | D17: Single instance | E17: Person | F17: The person who has this role. | G17: Workday Delivered | I17: Roles | J17: Default Areas | K17: Links to the underlying Person; same person can hold multiple worker records.
A18: 14 | B18: 1. Identity & Name | C18: Photo | D18: Single instance | E18: Image | F18: Returns the photo for the worker. | G18: Workday Delivered | I18: Basic Bio | J18: Default Areas | K18: Worker photo image; used in org charts and directories.
A19: 15 | B19: 1. Identity & Name | C19: Previous Worker ID | D19: Text | F19: Answer for the previous worker ID question on the job application. | G19: Workday Delivered | I19: Recruiting | J19: Default Areas | K19: ID from a previous record (for example a rehire or conversion); helps reconcile history.
A20: 16 | B20: 2. Worker Status & Classification | C20: Worker Type | D20: Single instance | E20: Worker Type | F20: The worker type (employee or contingent worker) for a worker. | G20: Workday Delivered | I20: Employment | J20: Security Attribute - System User | K20: Employee vs. Contingent Worker. The most common top-level report filter.
A21: 17 | B21: 2. Worker Status & Classification | C21: Employee Type | D21: Multi-instance | E21: Employee Type | F21: The employee type for the employee's primary position. | G21: Workday Delivered | I21: Benefits Eligibility | J21: Benefits Eligibility | K21: Regular, Temporary, Fixed Term and so on (tenant-configured). Multi-instance: one value per position.
A22: 18 | B22: 2. Worker Status & Classification | C22: Contingent Worker Type | D22: Single instance | E22: Contingent Worker Type | F22: Contains the type of contingent worker. | G22: Workday Delivered | I22: Benefits Eligibility | J22: Security Attribute - System User | K22: Contractor, Consultant, Vendor and so on, for contingent workers.
A23: 19 | B23: 2. Worker Status & Classification | C23: Worker is Contingent Worker | D23: Boolean | F23: Returns true if this Worker is a Contingent Worker. | G23: Workday Delivered | I23: Benefits Eligibility | J23: Benefits Eligibility | K23: Boolean shortcut for filters and calculated fields.
A24: 20 | B24: 2. Worker Status & Classification | C24: Active Status (Date As Of) | D24: Boolean | F24: Returns 'Yes' if the worker is active as of the Date As Of calculated field. Excludes workers who are on certain types of leave or who are terminated. | G24: Workday Delivered | I24: Job & Position | J24: Default Areas | K24: True when the worker is active as of the report's effective date.
A25: 21 | B25: 2. Worker Status & Classification | C25: Terminated | D25: Boolean | F25: True if worker's primary position is terminated or if the contract has ended. Use for business process condition rules but not for custom reports. Use Terminated (based on report date) for custom reports. | G25: Workday Delivered | I25: Employment | J25: Security Attribute - System User | K25: Boolean; combine with Termination Date for leaver reporting.
A26: 22 | B26: 2. Worker Status & Classification | C26: On Leave | D26: Boolean | F26: Identifies if an employee is on leave. | G26: Workday Delivered | I26: Benefits Eligibility | J26: Security Attribute - System User | K26: True while the worker is on an approved leave of absence.
A27: 23 | B27: 2. Worker Status & Classification | C27: Is Manager | D27: Boolean | F27: Identifies if the worker has a manager role. | G27: Workday Delivered | I27: Employment | J27: Security Attribute - System User | K27: True when the worker manages a supervisory organization.
A28: 24 | B28: 2. Worker Status & Classification | C28: Is Rehire | D28: Boolean | F28: Returns "Yes" if the processing worker is a rehire at the processing moment. A worker is considered to be a rehire if they have been hired more than once in the past and they are not terminated. | G28: Workday Delivered | I28: Job & Position | J28: Default Areas | K28: Flags workers who were previously employed.
A29: 25 | B29: 2. Worker Status & Classification | C29: Is Retiree | D29: Boolean | F29: Indicates whether a worker is a retiree. | G29: Workday Delivered | I29: Benefits Eligibility | J29: Benefits Eligibility | K29: Flags workers in a retiree status.
A30: 26 | B30: 2. Worker Status & Classification | C30: Time Type | D30: Single instance | E30: Time Type | F30: The position time type for the worker's primary position. | G30: Workday Delivered | I30: Employment | J30: Security Attribute - System User | K30: Full time or Part time.
A31: 27 | B31: 2. Worker Status & Classification | C31: Pay Rate Type | D31: Single instance | E31: Pay Rate Type | F31: The pay rate type for an employee's position and is used by payroll. | G31: Workday Delivered | I31: Benefits Eligibility | J31: Security Attribute - System User | K31: Salary vs. Hourly.
A32: 28 | B32: 2. Worker Status & Classification | C32: Exempt | D32: Boolean | F32: Returns "Yes" if the worker's primary position is exempt from overtime. | G32: Workday Delivered | I32: Employment | J32: Security Attribute - System User | K32: FLSA exempt flag (US). Use for overtime eligibility reporting.
A33: 29 | B33: 2. Worker Status & Classification | C33: FTE | D33: Numeric | F33: The full time equivalent for the worker's primary position. | G33: Workday Delivered | I33: Benefits Eligibility | J33: Benefits Eligibility | K33: Full-time-equivalent value of the primary position (for example 1.0 or 0.5).
A34: 30 | B34: 2. Worker Status & Classification | C34: Scheduled Weekly Hours | D34: Numeric | F34: The weekly hours for the worker's primary position. This is used in the Full Time Equivalent calculation: Scheduled Weekly Hours / Standard Weekly Hours. | G34: Workday Delivered | I34: Benefits Eligibility | J34: Benefits Eligibility | K34: Hours the worker is scheduled to work each week.
A35: 31 | B35: 2. Worker Status & Classification | C35: Default Weekly Hours | D35: Numeric | F35: The standard hours for the worker's primary position. Usually this is equal to the location standard hours but can be overridden at the position level. This is used in the calculation for Full Time Equivalent: Scheduled Weekly Hours / Standard Weekly Hours. | G35: Workday Delivered | I35: Job & Position | J35: Default Areas | K35: Standard full-time hours for the location or position; compare with scheduled hours.
A36: 32 | B36: 3. Key Dates & Service | C36: Hire Date | D36: Date | F36: The worker's most recent hire date. This report field cannot be effective dated. | G36: Workday Delivered | I36: Benefits Eligibility | J36: Security Attribute - System User | K36: Most recent hire date. Basis for most service calculations.
A37: 33 | B37: 3. Key Dates & Service | C37: Original Hire Date | D37: Date | F37: The date when the employee was first hired. | G37: Workday Delivered | I37: Benefits Eligibility | J37: Benefits Eligibility | K37: First-ever hire date; differs from Hire Date for rehires.
A38: 34 | B38: 3. Key Dates & Service | C38: Continuous Service Date | D38: Date | F38: Employee service date taking into account breaks in service. | G38: Workday Delivered | I38: Employment | J38: Benefits Eligibility | K38: Date used for continuous service and benefits eligibility.
A39: 35 | B39: 3. Key Dates & Service | C39: Seniority Date | D39: Date | F39: The seniority date for the worker. | G39: Workday Delivered | I39: Benefits Eligibility | J39: Benefits Eligibility | K39: Used for seniority-based rules (for example unions and layoffs).
A40: 36 | B40: 3. Key Dates & Service | C40: Company Service Date | D40: Date | F40: Company Service Date for the Worker. | G40: Workday Delivered | I40: Benefits Eligibility | J40: Benefits Eligibility | K40: Service date at the current company.
A41: 37 | B41: 3. Key Dates & Service | C41: Probation End Date | D41: Date | F41: The probation period end date for the worker's primary position. | G41: Workday Delivered | H41: Effective Date | I41: Probation Period | J41: Default Areas | K41: End of the probation period.
...

Sheet Field Types
A1: Field Types Explained
A2: Counts are live formulas over the All Worker Fields tab.
A4: Field Type | B4: Fields | C4: % of Total | D4: What it returns | E4: How to use it in reports | F4: Common examples
A5: Text | B5: =COUNTIF('All Worker Fields'!D:D,A5) -> 600 | C5: =IFERROR(B5/SUM($B$5:$B$13),0) -> 0.18438844 | D5: A plain string value. | E5: Filter with "contains" / "equal to". Best for exports and integrations. Cannot be drilled into. | F5: Employee ID, Email - Primary Work, Business Title, Cost Center - ID
A6: Numeric | B6: =COUNTIF('All Worker Fields'!D:D,A6) -> 194 | C6: =IFERROR(B6/SUM($B$5:$B$13),0) -> 0.059618931 | D6: A number (integer or decimal). | E6: Sort, sum, average and band. Use for maths in calculated fields. | F6: FTE, Age, Years of Service, Compa-Ratio
A7: Currency | B7: =COUNTIF('All Worker Fields'!D:D,A7) -> 136 | C7: =IFERROR(B7/SUM($B$5:$B$13),0) -> 0.041794714 | D7: A monetary amount; the currency is held separately. | E7: Always show the matching Currency (and Frequency) field, or use the "Annualized in USD / Reporting Currency" variants to compare across countries. | F7: Total Base Pay - Amount, Hourly Rate - Amount
A8: Date | B8: =COUNTIF('All Worker Fields'!D:D,A8) -> 230 | C8: =IFERROR(B8/SUM($B$5:$B$13),0) -> 0.070682237 | D8: A calendar date. | E8: Filter with relative dates (for example "in the last 30 days"); use Date Difference calculated fields for tenure. | F8: Hire Date, Termination Date, Date of Birth
A9: Boolean | B9: =COUNTIF('All Worker Fields'!D:D,A9) -> 457 | C9: =IFERROR(B9/SUM($B$5:$B$13),0) -> 0.14044253 | D9: True / False. | E9: Ideal for report filters and condition logic in calculated fields and business process conditions. | F9: Is Manager, On Leave, Terminated, Exempt
A10: Single instance | B10: =COUNTIF('All Worker Fields'!D:D,A10) -> 608 | C10: =IFERROR(B10/SUM($B$5:$B$13),0) -> 0.18684696 | D10: Exactly one related business object. | E10: Shows the object's display name; drill in (or use "Lookup Related Value") to reach the object's own fields. Use as a group-by in matrix reports. | F10: Supervisory Organization, Location, Job Profile, Company
A11: Multi-instance | B11: =COUNTIF('All Worker Fields'!D:D,A11) -> 927 | C11: =IFERROR(B11/SUM($B$5:$B$13),0) -> 0.28488015 | D11: Zero or more related business objects. | E11: Use subfilters, "Extract Multi-Instance", "Count Related Instances" or a secondary business object in advanced reports. Watch for row multiplication. | F11: Worker's Manager, Employee Type, Phone Numbers, Skills
A12: Self referencing instance | B12: =COUNTIF('All Worker Fields'!D:D,A12) -> 96 | C12: =IFERROR(B12/SUM($B$5:$B$13),0) -> 0.029502151 | D12: The instance itself (or the same object type, used as a reference). | E12: Used to identify the row's own instance, for example the Worker field on the Worker object, or plan dimensions. | F12: Worker, Plan Dimension as Job Level
A13: Rich Text | B13: =COUNTIF('All Worker Fields'!D:D,A13) -> 6 | C13: =IFERROR(B13/SUM($B$5:$B$13),0) -> 0.0018438844 | D13: Formatted text (HTML). | E13: Display only; formatting may not export cleanly to Excel or integrations. | F13: Potential Assessment Value 1
A14: Total | B14: =SUM(B5:B13) -> 3254 | C14: =SUM(C5:C13) -> 1
A16: Field Source
A17: Field Source | B17: Fields | C17: % of Total | D17: Meaning
A18: Workday Delivered | B18: =COUNTIF('All Worker Fields'!C:C,A18) -> 2835 | C18: =IFERROR(B18/SUM($B$18:$B$20),0) -> 0.8712354 | D18: Delivered and maintained by Workday.
A19: Calculated | B19: =COUNTIF('All Worker Fields'!C:C,A19) -> 408 | C19: =IFERROR(B19/SUM($B$18:$B$20),0) -> 0.12538414 | D19: Tenant-built calculated field. Check its logic before reuse; it may be tenant-specific.
A20: Custom Field | B20: =COUNTIF('All Worker Fields'!C:C,A20) -> 11 | C20: =IFERROR(B20/SUM($B$18:$B$20),0) -> 0.0033804548 | D20: Tenant-defined custom object or field.

Sheet Categories
A1: Field Categories
A2: Every category in the Worker PBO with live field counts. Sorted by size.
A4: Category | B4: Total Fields | C4: Common Fields in Handbook
A5: Uncategorized | B5: =COUNTIF('All Worker Fields'!G:G,A5) -> 401 | C5: =COUNTIFS('All Worker Fields'!G:G,A5,'All Worker Fields'!I:I,"Yes") -> 1
A6: Worker Tax Elections | B6: =COUNTIF('All Worker Fields'!G:G,A6) -> 219 | C6: =COUNTIFS('All Worker Fields'!G:G,A6,'All Worker Fields'!I:I,"Yes") -> 0
A7: Benefits Eligibility | B7: =COUNTIF('All Worker Fields'!G:G,A7) -> 205 | C7: =COUNTIFS('All Worker Fields'!G:G,A7,'All Worker Fields'!I:I,"Yes") -> 39
A8: Compensation | B8: =COUNTIF('All Worker Fields'!G:G,A8) -> 205 | C8: =COUNTIFS('All Worker Fields'!G:G,A8,'All Worker Fields'!I:I,"Yes") -> 18
A9: Payroll | B9: =COUNTIF('All Worker Fields'!G:G,A9) -> 190 | C9: =COUNTIFS('All Worker Fields'!G:G,A9,'All Worker Fields'!I:I,"Yes") -> 2
A10: Organization | B10: =COUNTIF('All Worker Fields'!G:G,A10) -> 159 | C10: =COUNTIFS('All Worker Fields'!G:G,A10,'All Worker Fields'!I:I,"Yes") -> 17
A11: Address & Phone | B11: =COUNTIF('All Worker Fields'!G:G,A11) -> 113 | C11: =COUNTIFS('All Worker Fields'!G:G,A11,'All Worker Fields'!I:I,"Yes") -> 7
A12: Talent | B12: =COUNTIF('All Worker Fields'!G:G,A12) -> 107 | C12: =COUNTIFS('All Worker Fields'!G:G,A12,'All Worker Fields'!I:I,"Yes") -> 7
A13: Job & Position | B13: =COUNTIF('All Worker Fields'!G:G,A13) -> 100 | C13: =COUNTIFS('All Worker Fields'!G:G,A13,'All Worker Fields'!I:I,"Yes") -> 18
A14: Basic Bio | B14: =COUNTIF('All Worker Fields'!G:G,A14) -> 91 | C14: =COUNTIFS('All Worker Fields'!G:G,A14,'All Worker Fields'!I:I,"Yes") -> 10
A15: Recruiting | B15: =COUNTIF('All Worker Fields'!G:G,A15) -> 83 | C15: =COUNTIFS('All Worker Fields'!G:G,A15,'All Worker Fields'!I:I,"Yes") -> 2
A16: Time Off | B16: =COUNTIF('All Worker Fields'!G:G,A16) -> 82 | C16: =COUNTIFS('All Worker Fields'!G:G,A16,'All Worker Fields'!I:I,"Yes") -> 2
... A137: Year End | B137: =COUNTIF('All Worker Fields'!G:G,A137) -> 1 | C137: =COUNTIFS('All Worker Fields'!G:G,A137,'All Worker Fields'!I:I,"Yes") -> 0

Sheet Related Objects
A1: Related Business Objects (RBO)
A2: Objects reachable from Worker. "Number of Links" is from Worker_RBO.xlsx; linking fields are taken from the PBO.
A4: Related Business Object | B4: Number of Links (RBO) | C4: Single-instance Links | D4: Multi-instance Links | E4: Example Worker Fields that Return this Object
A5: Worker | B5: 88 | C5: =COUNTIFS('All Worker Fields'!E:E,A5,'All Worker Fields'!D:D,"Single instance") -> 40 | D5: =COUNTIFS('All Worker Fields'!E:E,A5,'All Worker Fields'!D:D,"Multi-instance") -> 29 | E5: All Managers in Management Chain; Direct Reports (Employees); Manager - Level 01; Manager - Level 02; Worker ...
A6: Position | B6: 47 | C6: =COUNTIFS('All Worker Fields'!E:E,A6,'All Worker Fields'!D:D,"Single instance") -> 24 | D6: =COUNTIFS('All Worker Fields'!E:E,A6,'All Worker Fields'!D:D,"Multi-instance") -> 18 | E6: All Positions; Position; Additional Jobs; Additional Jobs - All; Additional Jobs if Enabled; All Effective Positions ...
A7: Organization | B7: 35 | C7: =COUNTIFS('All Worker Fields'!E:E,A7,'All Worker Fields'!D:D,"Single instance") -> 11 | D7: =COUNTIFS('All Worker Fields'!E:E,A7,'All Worker Fields'!D:D,"Multi-instance") -> 21 | E7: Organizations Managed; Supervisory Organization; Assigned Organization; Assigned Organizations (Benefit Jobs); CF ESI Superior Orgnization; CF_ESI PC on Worker ...
A8: Location | B8: 30 | C8: =COUNTIFS('All Worker Fields'!E:E,A8,'All Worker Fields'!D:D,"Single instance") -> 18 | D8: =COUNTIFS('All Worker Fields'!E:E,A8,'All Worker Fields'!D:D,"Multi-instance") -> 11 | E8: Location; All Locations; All Locations (Benefit Jobs); All Locations (Benefits); Cost Center - Primary Locations; Headcount Plan Template Location Filters ...
A9: Currency | B9: 29 | C9: =COUNTIFS('All Worker Fields'!E:E,A9,'All Worker Fields'!D:D,"Single instance") -> 29 | D9: =COUNTIFS('All Worker Fields'!E:E,A9,'All Worker Fields'!D:D,"Multi-instance") -> 0 | E9: Total Base Pay - Currency; Benefits Annual Rate Currency; Company or Company Hierarchy Currency; Compensation Range - Currency; Competitive Market Target Benchmark - Currency; Currency for Primary Position ...
A10: Abstract Review Rating | B10: 26 | C10: =COUNTIFS('All Worker Fields'!E:E,A10,'All Worker Fields'!D:D,"Single instance") -> 22 | D10: =COUNTIFS('All Worker Fields'!E:E,A10,'All Worker Fields'!D:D,"Multi-instance") -> 4 | E10: Last Review - Overall Rating; Average Project Rating; Calibration: Column Section Rating; Calibration: Overall Performance Rating; Calibration: Row Section Rating; Calibration: Talent Based Performance Rating ...
A11: Frequency | B11: 24 | C11: =COUNTIFS('All Worker Fields'!E:E,A11,'All Worker Fields'!D:D,"Single instance") -> 24 | D11: =COUNTIFS('All Worker Fields'!E:E,A11,'All Worker Fields'!D:D,"Multi-instance") -> 0 | E11: Primary Compensation Basis - Frequency; Total Base Pay - Frequency; Compensation Range - Frequency; Frequency - Payroll; Frequency for Primary Position; Pay Frequency - Payroll ...
A12: Worker Tax Election | B12: 21 | C12: =COUNTIFS('All Worker Fields'!E:E,A12,'All Worker Fields'!D:D,"Single instance") -> 0 | D12: =COUNTIFS('All Worker Fields'!E:E,A12,'All Worker Fields'!D:D,"Multi-instance") -> 21 | E12: All Local County Withholding (Resident); All Local County Withholding (Work); All State Withholding Elections; Erroneously Has Exempt Reason or Domicile State; Erroneously Has MSRR Exempt or Exempt; Erroneously Has Spouse Indicator, Marital Status, or Reciprocity Tax Credit ...
A13: Address | B13: 20 | C13: =COUNTIFS('All Worker Fields'!E:E,A13,'All Worker Fields'!D:D,"Single instance") -> 8 | D13: =COUNTIFS('All Worker Fields'!E:E,A13,'All Worker Fields'!D:D,"Multi-instance") -> 11 | E13: Primary Home Address; Primary Work Address; Addresses; Addresses - Local; Addresses without Default Work Address; All Home Addresses ...
A14: Personal Information Configurable Field Country Agnostic | B14: 18 | C14: =COUNTIFS('All Worker Fields'!E:E,A14,'All Worker Fields'!D:D,"Single instance") -> 0 | D14: =COUNTIFS('All Worker Fields'!E:E,A14,'All Worker Fields'!D:D,"Multi-instance") -> 18 | E14: Non Country Specific Section 1 - Field 1; Non Country Specific Section 1 - Field 1 (Locale Sensitive); Non Country Specific Section 1 - Field 2; Non Country Specific Section 1 - Field 2 (Locale Sensitive); Non Country Specific Section 1 - Field 3; Non Country Specific Section 1 - Field 3 (Locale Sensitive) ...
A15: Personal Information Configurable Field for Country | B15: 18 | C15: =COUNTIFS('All Worker Fields'!E:E,A15,'All Worker Fields'!D:D,"Single instance") -> 0 | D15: =COUNTIFS('All Worker Fields'!E:E,A15,'All Worker Fields'!D:D,"Multi-instance") -> 18 | E15: Country Specific Section 1 - Field 1; Country Specific Section 1 - Field 1 (Locale Sensitive); Country Specific Section 1 - Field 2; Country Specific Section 1 - Field 2 (Locale Sensitive); Country Specific Section 1 - Field 3; Country Specific Section 1 - Field 3 (Locale Sensitive) ...
A16: Union | B16: 18 | C16: =COUNTIFS('All Worker Fields'!E:E,A16,'All Worker Fields'!D:D,"Single instance") -> 0 | D16: =COUNTIFS('All Worker Fields'!E:E,A16,'All Worker Fields'!D:D,"Multi-instance") -> 18 | E16: Unions Active; Active Dues Paying Unions as of Period Start Date; Active Dues Paying Unions as of Sub Period End Date; Active Unions as of Leave Start Date; Active Unions as of Period End Date; Active Unions as of Period Start Date ...
... A84: Benefit Change | B84: 4 | C84: =COUNTIFS('All Worker Fields'!E:E,A84,'All Worker Fields'!D:D,"Single instance") -> 0 | D84: =COUNTIFS('All Worker Fields'!E:E,A84,'All Worker Fields'!D:D,"Multi-instance") -> 4 | E84: Benefit Changes; Benefit Changes by Plan; Insurance Election Changes; RPT EMI Worker Benefit Changes within prompts
A85: Communication Method Usage | B85: 4 | C85: =COUNTIFS('All Worker Fields'!E:E,A85,'All Worker Fields'!D:D,"Single instance") -> 0 | D85: =COUNTIFS('All Worker Fields'!E:E,A85,'All Worker Fields'!D:D,"Multi-instance") -> 0
A86: Compensation Grade | B86: 4 | C86: =COUNTIFS('All Worker Fields'!E:E,A86,'All Worker Fields'!D:D,"Single instance") -> 2 | D86: =COUNTIFS('All Worker Fields'!E:E,A86,'All Worker Fields'!D:D,"Multi-instance") -> 1 | E86: Compensation Grade; Compensation Grades (Benefit Jobs); Plan Dimension as Compensation Grade; Retained Compensation Grade
A87: Country and Nationality | B87: 4 | C87: =COUNTIFS('All Worker Fields'!E:E,A87,'All Worker Fields'!D:D,"Single instance") -> 1 | D87: =COUNTIFS('All Worker Fields'!E:E,A87,'All Worker Fields'!D:D,"Multi-instance") -> 3 | E87: Primary Nationality (Worker) - Locale Sensitive; Additional Nationalities (Worker); Additional Nationalities (Worker) - Locale Sensitive; All Nationalities (Worker)
A88: Disability | B88: 4 | C88: =COUNTIFS('All Worker Fields'!E:E,A88,'All Worker Fields'!D:D,"Single instance") -> 0 | D88: =COUNTIFS('All Worker Fields'!E:E,A88,'All Worker Fields'!D:D,"Multi-instance") -> 4 | E88: Disability (Locale Sensitive and Country Securable); Disability (Locale Sensitive); Disability - Active and Inactive (Locale Sensitive and Country Securable); Disability - Active and Inactive (Locale Sensitive)
A89: External Pay Group (Do Not Use) | B89: 4 | C89: =COUNTIFS('All Worker Fields'!E:E,A89,'All Worker Fields'!D:D,"Single instance") -> 3 | D89: =COUNTIFS('All Worker Fields'!E:E,A89,'All Worker Fields'!D:D,"Multi-instance") -> 1 | E89: External Pay Group; External Pay Group as of Period End Date; External Pay Group as of Period Start Date; External Pay Groups (Benefit Jobs)
A90: External Payroll Actual | B90: 4 | C90: =COUNTIFS('All Worker Fields'!E:E,A90,'All Worker Fields'!D:D,"Single instance") -> 0 | D90: =COUNTIFS('All Worker Fields'!E:E,A90,'All Worker Fields'!D:D,"Multi-instance") -> 4 | E90: External Payroll Actuals (All for Primary Job); External Payroll Actuals (All for Worker); External Payroll Actuals (Completed for Primary Job); External Payroll Actuals (Completed for Worker)
A91: Feedback Given | B91: 4 | C91: =COUNTIFS('All Worker Fields'!E:E,A91,'All Worker Fields'!D:D,"Single instance") -> 0 | D91: =COUNTIFS('All Worker Fields'!E:E,A91,'All Worker Fields'!D:D,"Multi-instance") -> 3 | E91: Feedback Given; Feedback Received; Feedback Received - Anytime
A92: Flex Team Opening | B92: 4 | C92: =COUNTIFS('All Worker Fields'!E:E,A92,'All Worker Fields'!D:D,"Single instance") -> 0 | D92: =COUNTIFS('All Worker Fields'!E:E,A92,'All Worker Fields'!D:D,"Multi-instance") -> 4 | E92: Active Flex Teams; Completed Flex Teams; Flex Teams; Interested Flex Teams
A93: Former Worker | B93: 4 | C93: =COUNTIFS('All Worker Fields'!E:E,A93,'All Worker Fields'!D:D,"Single instance") -> 3 | D93: =COUNTIFS('All Worker Fields'!E:E,A93,'All Worker Fields'!D:D,"Multi-instance") -> 0 | E93: Former Worker; Linked Prior Worker (Former); Merged Former Worker
A94: Hukou Type | B94: 4 | C94: =COUNTIFS('All Worker Fields'!E:E,A94,'All Worker Fields'!D:D,"Single instance") -> 4 | D94: =COUNTIFS('All Worker Fields'!E:E,A94,'All Worker Fields'!D:D,"Multi-instance") -> 0 | E94: Hukou Type; Hukou Type (Country Securable); Hukou Type as of Period End Date; Hukou Type as of Period Start Date
A95: Internet Email Address | B95: 4 | C95: =COUNTIFS('All Worker Fields'!E:E,A95,'All Worker Fields'!D:D,"Single instance") -> 0 | D95: =COUNTIFS('All Worker Fields'!E:E,A95,'All Worker Fields'!D:D,"Multi-instance") -> 4 | E95: Email - Home; Email - Work; Emails; Public Email Addresses
A96: Leave Type | B96: 4 | C96: =COUNTIFS('All Worker Fields'!E:E,A96,'All Worker Fields'!D:D,"Single instance") -> 0 | D96: =COUNTIFS('All Worker Fields'!E:E,A96,'All Worker Fields'!D:D,"Multi-instance") -> 4 | E96: Leave Type; Active Leave Types that Track Balance; All Eligible Leave Types for Worker; Leave Types for Worker
A97: Location Hierarchy | B97: 4 | C97: =COUNTIFS('All Worker Fields'!E:E,A97,'All Worker Fields'!D:D,"Single instance") -> 0 | D97: =COUNTIFS('All Worker Fields'!E:E,A97,'All Worker Fields'!D:D,"Multi-instance") -> 3 | E97: Location Hierarchy; Location Hierarchy for Worker as of Period End Date; Location Hierarchy for Worker as of Period Start Date; Plan Dimension as Location Hierarchy
... A144: Personal Information for Country | B144: 3 | C144: =COUNTIFS('All Worker Fields'!E:E,A144,'All Worker Fields'!D:D,"Single instance") -> 2 | D144: =COUNTIFS('All Worker Fields'!E:E,A144,'All Worker Fields'!D:D,"Multi-instance") -> 1 | E144: All Personal Information for Country; Personal Information for Country; Personal Information for Country of Primary Position
A145: Phone Interface | B145: 3 | C145: =COUNTIFS('All Worker Fields'!E:E,A145,'All Worker Fields'!D:D,"Single instance") -> 0 | D145: =COUNTIFS('All Worker Fields'!E:E,A145,'All Worker Fields'!D:D,"Multi-instance") -> 0
A146: Project | B146: 3 | C146: =COUNTIFS('All Worker Fields'!E:E,A146,'All Worker Fields'!D:D,"Single instance") -> 0 | D146: =COUNTIFS('All Worker Fields'!E:E,A146,'All Worker Fields'!D:D,"Multi-instance") -> 2 | E146: Plan Dimension as Project; Worker Projects - Directly Assigned; Worker Projects - Do Not Use
A147: Project Resource Plan Detail | B147: 3 | C147: =COUNTIFS('All Worker Fields'!E:E,A147,'All Worker Fields'!D:D,"Single instance") -> 0 | D147: =COUNTIFS('All Worker Fields'!E:E,A147,'All Worker Fields'!D:D,"Multi-instance") -> 3 | E147: Assigned Resource Plan Details for Worker within Date Range; Resource Plan Details; Resource Plan Lines with Pending Request
A148: Project Role | B148: 3 | C148: =COUNTIFS('All Worker Fields'!E:E,A148,'All Worker Fields'!D:D,"Single instance") -> 0 | D148: =COUNTIFS('All Worker Fields'!E:E,A148,'All Worker Fields'!D:D,"Multi-instance") -> 2 | E148: Plan Dimension as Project Role; Project Roles; Project Roles for Worker's Time
A149: Pronoun | B149: 3 | C149: =COUNTIFS('All Worker Fields'!E:E,A149,'All Worker Fields'!D:D,"Single instance") -> 1 | D149: =COUNTIFS('All Worker Fields'!E:E,A149,'All Worker Fields'!D:D,"Multi-instance") -> 1 | E149: Pronoun (Locale Sensitive); Pronouns (Locale Sensitive)
A150: Rank | B150: 3 | C150: =COUNTIFS('All Worker Fields'!E:E,A150,'All Worker Fields'!D:D,"Single instance") -> 1 | D150: =COUNTIFS('All Worker Fields'!E:E,A150,'All Worker Fields'!D:D,"Multi-instance") -> 2 | E150: Academic Rank for Committee Candidate; Academic Rank for Primary Academic Appointment; Academic Ranks
A151: Scheduling Organization | B151: 3 | C151: =COUNTIFS('All Worker Fields'!E:E,A151,'All Worker Fields'!D:D,"Single instance") -> 2 | D151: =COUNTIFS('All Worker Fields'!E:E,A151,'All Worker Fields'!D:D,"Multi-instance") -> 1 | E151: All Scheduling Organizations for Worker; Primary High Level Scheduling Organization; Primary Scheduling Organization
A152: Sexual Orientation | B152: 3 | C152: =COUNTIFS('All Worker Fields'!E:E,A152,'All Worker Fields'!D:D,"Single instance") -> 1 | D152: =COUNTIFS('All Worker Fields'!E:E,A152,'All Worker Fields'!D:D,"Multi-instance") -> 1 | E152: Sexual Orientation (Locale Sensitive); Sexual Orientations (Locale Sensitive)
A153: Skill Detail | B153: 3 | C153: =COUNTIFS('All Worker Fields'!E:E,A153,'All Worker Fields'!D:D,"Single instance") -> 0 | D153: =COUNTIFS('All Worker Fields'!E:E,A153,'All Worker Fields'!D:D,"Multi-instance") -> 3 | E153: All Mentor Skills; Skill for Worker; Suggested Skills
A154: Skill Item Promptable | B154: 3 | C154: =COUNTIFS('All Worker Fields'!E:E,A154,'All Worker Fields'!D:D,"Single instance") -> 0 | D154: =COUNTIFS('All Worker Fields'!E:E,A154,'All Worker Fields'!D:D,"Multi-instance") -> 3 | E154: All Candidate Skills; All Skills; Skill Interests
...

Sheet All Worker Fields
A1: Field Name | B1: Description | C1: Field Source | D1: Field Type | E1: Related Business Object | F1: Built-in Prompts | G1: Category | H1: Authorized Usage | I1: Common?
A2: (Active) Relocation - Long Term Areas | B2: The active relocation areas that the employee is willing to relocate to in the long term. | C2: Workday Delivered | D2: Multi-instance | E2: Relocation Area | G2: Career Development | H2: Default Areas
A3: (Active) Relocation - Short Term Areas | B3: The active relocation areas that the employee is willing to relocate to in the short term. | C3: Workday Delivered | D3: Multi-instance | E3: Relocation Area | G3: Career Development | H3: Default Areas
A4: Aboriginal/Indigenous Identification | B4: A person's response to whether or not they identify as aboriginal/indigenous. | C4: Workday Delivered | D4: Single instance | E4: Aboriginal/Indigenous Identification Selection | G4: Basic Bio | H4: Default Areas
A5: Aboriginal/Indigenous Identification Details | B5: The aboriginal/indigenous identification values for a person. | C5: Workday Delivered | D5: Multi-instance | E5: Aboriginal/Indigenous Identification Details | G5: Basic Bio | H5: Default Areas
A6: ABS CF EE Annual Work Period is F10 | C6: Calculated | D6: Single instance | E6: Worker | G6: Uncategorized | H6: Calculation Engine (Payroll/Absence)
A7: ABS CF EE Total FTE (Max 1 FTE) | C7: Calculated | D7: Numeric | G7: Uncategorized | H7: Default Areas
A8: ABS CF LRV Worker is Absence Administrator or Partner | C8: Calculated | D8: Boolean | G8: Security | H8: Calculation Engine (Payroll/Absence)
A9: ABS CF TF Total Blended FTE > 1 | C9: Calculated | D9: Boolean | G9: Leave of Absence | H9: Calculation Engine (Payroll/Absence)
A10: ABS CF Worker AWP is F10 | C10: Calculated | D10: Boolean | G10: Uncategorized | H10: Calculation Engine (Payroll/Absence)
A11: ABS CF Worker's FTE * 1040 | C11: Calculated | D11: Numeric | G11: Uncategorized | H11: Default Areas
A12: ABS CF Worker's FTE * 480 | C12: Calculated | D12: Numeric | G12: Uncategorized | H12: Default Areas
A13: Absence Case Event | B13: Returns Absence Case Events For Worker. | C13: Workday Delivered | D13: Multi-instance | E13: Absence Case Event | G13: Worker | H13: Default Areas
A14: Absence Occurrences for Worker in Date Range | B14: The absence occurrences for the worker within the date range. Workday groups absences that occur on either side of nonworking days into 1 consecutive absence. | C14: Workday Delivered | D14: Multi-instance | E14: Absence Occurrence | F14: Absence Occurrence Units (Hours) | G14: Time Off | H14: Default Areas
A15: ACA IRS 1094-C Reporting - Included in Total Employee Count for August | B15: This CRF is specific for ACA IRS Reporting. Returns True if the worker was included in the most recent calculation of 1094-C Total Employee counts for the month of August. Uses Entry Moment of when the calculate job (Calculate 1094-C Total and Full Time Employee Counts By Month) was run. | C15: Workday Delivered | D15: Boolean | F15: Month | G15: ACA IRS Reporting | H15: Default Areas
A16: ACA IRS 1094-C Reporting - Included in Total Employee Count for February | B16: This CRF is specific for ACA IRS Reporting. Returns True if the worker was included in the most recent calculation of 1094-C Total Employee counts for the month of February. Uses Entry Moment of when the calculate job (Calculate 1094-C Total and Full Time Employee Counts By Month) was run. | C16: Workday Delivered | D16: Boolean | F16: Month | G16: ACA IRS Reporting | H16: Default Areas
A17: ACA IRS 1094-C Reporting - Included in Total Employee Count for January | B17: This CRF is specific for ACA IRS Reporting. Returns True if the worker was included in the most recent calculation of 1094-C Total Employee counts for the month of January. Uses Entry Moment of when the calculate job (Calculate 1094-C Total and Full Time Employee Counts By Month) was run. | C17: Workday Delivered | D17: Boolean | F17: Month | G17: ACA IRS Reporting | H17: Default Areas
A18: ACA IRS 1094-C Reporting - Included in Total Employee Count for July | B18: This CRF is specific for ACA IRS Reporting. Returns True if the worker was included in the most recent calculation of 1094-C Total Employee counts for the month of July. Uses Entry Moment of when the calculate job (Calculate 1094-C Total and Full Time Employee Counts By Month) was run. | C18: Workday Delivered | D18: Boolean | F18: Month | G18: ACA IRS Reporting | H18: Default Areas
A19: ACA IRS 1094-C Reporting - Included in Total Employee Count for June | B19: This CRF is specific for ACA IRS Reporting. Returns True if the worker was included in the most recent calculation of 1094-C Total Employee counts for the month of June. Uses Entry Moment of when the calculate job (Calculate 1094-C Total and Full Time Employee Counts By Month) was run. | C19: Workday Delivered | D19: Boolean | F19: Month | G19: ACA IRS Reporting | H19: Default Areas
A20: ACA IRS 1094-C Reporting - Included in Total Employee Count for March | B20: This CRF is specific for ACA IRS Reporting. Returns True if the worker was included in the most recent calculation of 1094-C Total Employee counts for the month of March. Uses Entry Moment of when the calculate job (Calculate 1094-C Total and Full Time Employee Counts By Month) was run. | C20: Workday Delivered | D20: Boolean | F20: Month | G20: ACA IRS Reporting | H20: Default Areas
A21: ACA IRS 1094-C Reporting - Included in Total Employee Count for May | B21: This CRF is specific for ACA IRS Reporting. Returns True if the worker was included in the most recent calculation of 1094-C Total Employee counts for the month of May. Uses Entry Moment of when the calculate job (Calculate 1094-C Total and Full Time Employee Counts By Month) was run. | C21: Workday Delivered | D21: Boolean | F21: Month | G21: ACA IRS Reporting | H21: Default Areas
A22: ACA IRS 1094-C Reporting - Included in Total Employee Count for April | B22: This CRF is specific for ACA IRS Reporting. Returns True if the worker was included in the most recent calculation of 1094-C Total Employee counts for the month of April. Uses Entry Moment of when the calculate job (Calculate 1094-C Total and Full Time Employee Counts By Month) was run. | C22: Workday Delivered | D22: Boolean | F22: Month | G22: ACA IRS Reporting | H22: Default Areas
A23: ACA IRS 1094-C Reporting - Included in Total Employee Count for December | B23: This CRF is specific for ACA IRS Reporting. Returns True if the worker was included in the most recent calculation of 1094-C Total Employee counts for the month of December. Uses Entry Moment of when the calculate job (Calculate 1094-C Total and Full Time Employee Counts By Month) was run. | C23: Workday Delivered | D23: Boolean | F23: Month | G23: ACA IRS Reporting | H23: Default Areas
A24: ACA IRS 1094-C Reporting - Included in Total Employee Count for November | B24: This CRF is specific for ACA IRS Reporting. Returns True if the worker was included in the most recent calculation of 1094-C Total Employee counts for the month of November. Uses Entry Moment of when the calculate job (Calculate 1094-C Total and Full Time Employee Counts By Month) was run. | C24: Workday Delivered | D24: Boolean | F24: Month | G24: ACA IRS Reporting | H24: Default Areas
A25: ACA IRS 1094-C Reporting - Included in Total Employee Count for October | B25: This CRF is specific for ACA IRS Reporting. Returns True if the worker was included in the most recent calculation of 1094-C Total Employee counts for the month of October. Uses Entry Moment of when the calculate job (Calculate 1094-C Total and Full Time Employee Counts By Month) was run. | C25: Workday Delivered | D25: Boolean | F25: Month | G25: ACA IRS Reporting | H25: Default Areas
A26: ACA IRS 1094-C Reporting - Included in Total Employee Count for September | B26: This CRF is specific for ACA IRS Reporting. Returns True if the worker was included in the most recent calculation of 1094-C Total Employee counts for the month of September. Uses Entry Moment of when the calculate job (Calculate 1094-C Total and Full Time Employee Counts By Month) was run. | C26: Workday Delivered | D26: Boolean | F26: Month | G26: ACA IRS Reporting | H26: Default Areas
... A38: ACA IRS 1094-C Reporting - Worker Included in Full Time Count for September | B38: This CRF is specific for ACA IRS Reporting. Returns True if the worker was included in the most recent calculation of 1094-C full time Employee counts for the month of September. Uses Entry Moment of when the calculate job (Calculate 1094-C Total and Full Time Employee Counts By Month) was run. | C38: Workday Delivered | D38: Boolean | F38: Month | G38: ACA IRS Reporting | H38: Default Areas
A39: ACA Measurement Period Worker History Instances | B39: Returns all the ACA Measurement Period Worker History records/instances for a given worker/employee. | C39: Workday Delivered | D39: Multi-instance | E39: ACA Measurement Period Worker History | G39: Benefits | H39: Default Areas
A40: ACA Worker Hours And Wages Instances | B40: Returns all the ACA Worker Hours And Wages records/instances imported (via EIB/Web Service) for a given worker/employee. | C40: Workday Delivered | D40: Multi-instance | E40: Affordable Care Act Worker Hours And Wages | G40: Benefits Eligibility | H40: Benefits Eligibility
A41: Academic Affiliate | B41: Returns the academic affiliate object for the member. | C41: Workday Delivered | D41: Single instance | E41: Academic Affiliate | G41: Committee Memberships | H41: Default Areas
A42: Academic Appointment Identifiers | B42: All Academic Appointment Identifiers from the worker's current Academic Appointments. The "effective date" can be specified to return data that is current as of that date. If not specified, the current date is used. | C42: Workday Delivered | D42: Multi-instance | E42: Appointment Identifier | G42: Academic Appointments | H42: Default Areas
A43: Academic Appointment Tenured | B43: Returns true if any of the Worker's current Academic Appointments have a status of Tenured. The "effective date" can be specified to return data that is current as of that date. If not specified, the current date is used. | C43: Workday Delivered | D43: Boolean | G43: Academic Appointments | H43: Default Areas
A44: Academic Appointment Titles | B44: Contains the Academic Appointments for the Worker. In Report Writer, this field will display the Title, instead of the default display for an Academic Appointment. The "effective date" can be specified to return data that is current as of that date. If not specified, the current date is used. | C44: Workday Delivered | D44: Multi-instance | E44: Academic Appointment | G44: Academic Appointments | H44: Default Areas
A45: Academic Appointments | B45: Contains all the Academic Appointments for a Worker, past, present, and future, for all Academic Appointment Threads. | C45: Workday Delivered | D45: Multi-instance | E45: Academic Appointment | G45: Academic Appointments | H45: Default Areas
A46: Academic Appointments With Sabbatical Program | B46: All current Academic Appointments with Academic Track that includes Sabbatical Program. The "effective date" can be specified to return data that is current as of that date. If not specified, the current date is used. | C46: Workday Delivered | D46: Multi-instance | E46: Academic Appointment | G46: Academic Appointments | H46: Benefits Eligibility
A47: Academic Level for Committee Candidate | B47: The Academic Level for the committee member candidate. | C47: Workday Delivered | D47: Multi-instance | E47: Academic Level | G47: Committee Candidates | H47: Default Areas
A48: Academic Rank for Committee Candidate | B48: Returns the Academic Rank, if it exists, for a committee member candidate. | C48: Workday Delivered | D48: Multi-instance | E48: Rank | G48: Committee Candidates | H48: Default Areas
A49: Academic Rank for Primary Academic Appointment | B49: The Academic Rank for the Worker's primary Academic Appointment. The primary flag is located on the appointment's Identifier. | C49: Workday Delivered | D49: Single instance | E49: Rank | G49: Academic Appointments | H49: Default Areas
A50: Academic Ranks | B50: All Academic Ranks from the worker's current Academic Appointments. The "effective date" can be specified to return data that is current as of that date. If not specified, the current date is used. | C50: Workday Delivered | D50: Multi-instance | E50: Rank | G50: Academic Appointments | H50: Benefits Eligibility
A51: Academic Tenure Date | B51: The date which the worker received academic tenure. If the date is specified in an Academic Appointment, that date is used. If that date is not specified, but the tenure date is specified in the Maintain Tenure Business Process (deprecated in W15), this date is used. | C51: Workday Delivered | D51: Date | G51: Employment | H51: Benefits Eligibility
...
